<robot name="robot">
  <link name="map"></link>
  <joint name="base_joint" type="fixed">
    <parent link="map" />
    <child link="base_link" />
    <origin xyz="0 0 0" rpy="0 0 0" />
  </joint>
  <link name="base_link">
    <visual>
      <origin xyz="0 0 0" rpy="0 0 0" />
      <geometry>
        <cylinder radius="0.5" length="1" />
      </geometry>
      <material name="base_link-material">
        <color rgba="0.2917706498067336 0.407240211891531 0.08021982030622662 1" />
      </material>
    </visual>
    <collision>
      <origin xyz="0 0 0" rpy="0 0 0" />
      <geometry>
        <cylinder radius="0.5" length="1" />
      </geometry>
    </collision>
    <inertial>
      <origin xyz="0 0 0" rpy="0 0 0" />
      <mass value="1" />
      <inertia ixx="0.3333333333333333" ixy="0" ixz="0" iyy="0.5" iyz="0" izz="0.3333333333333333" />
    </inertial>
  </link>
  <joint name="base_link_to_cylinder1" type="continuous">
    <parent link="base_link" />
    <child link="cylinder1" />
    <origin xyz="0 0 -1" rpy="0 0 0" />
    <axis xyz="0 0 1"/>
  </joint>
  <link name="cylinder1">
    <visual>
      <origin xyz="0 0 0" rpy="0 0 0" />
      <geometry>
        <cylinder radius="0.5" length="1" />
      </geometry>
      <material name="cylinder1-material">
        <color rgba="0.05286064701616472 0.46778379610254284 0.2874408377161099 1" />
      </material>
    </visual>
    <collision>
      <origin xyz="0 0 0" rpy="0 0 0" />
      <geometry>
        <cylinder radius="0.5" length="1" />
      </geometry>
    </collision>
    <inertial>
      <origin xyz="0 0 0" rpy="0 0 0" />
      <mass value="1" />
      <inertia ixx="0.3333333333333333" ixy="0" ixz="0" iyy="0.5" iyz="0" izz="0.3333333333333333" />
    </inertial>
  </link>
  <joint name="cylinder1_to_cylinder2" type="revolute">
    <parent link="cylinder1" />
    <child link="cylinder2" />
    <origin xyz="1 0 0" rpy="1.5707963267948963 0 0" />
    <axis xyz="0 0 1"/>
    <limit effort="1000.0" lower="-1.57" upper="1.57" velocity="0.5"/>  </joint>
  <link name="cylinder2">
    <visual>
      <origin xyz="0 0 0" rpy="0 0 0" />
      <geometry>
        <cylinder radius="0.5" length="1" />
      </geometry>
      <material name="cylinder2-material">
        <color rgba="0.05612849004241121 0.8962693533719567 0.06847816983662762 1" />
      </material>
    </visual>
    <collision>
      <origin xyz="0 0 0" rpy="0 0 0" />
      <geometry>
        <cylinder radius="0.5" length="1" />
      </geometry>
    </collision>
    <inertial>
      <origin xyz="0 0 0" rpy="0 0 0" />
      <mass value="1" />
      <inertia ixx="0.3333333333333333" ixy="0" ixz="0" iyy="0.5" iyz="0" izz="0.3333333333333333" />
    </inertial>
  </link>
  <joint name="cylinder2_to_cylinder3" type="continuous">
    <parent link="cylinder2" />
    <child link="cylinder3" />
    <origin xyz="1 0 0" rpy="-1.5707963267948966 2.220446049250313e-16 -1.5707963267948963" />
    <axis xyz="0 0 1"/>
  </joint>
  <link name="cylinder3">
    <visual>
      <origin xyz="0 0 0" rpy="0 0 0" />
      <geometry>
        <cylinder radius="0.5" length="1" />
      </geometry>
      <material name="cylinder3-material">
        <color rgba="0.8 0.8 0.2 1" />
      </material>
    </visual>
    <collision>
      <origin xyz="0 0 0" rpy="0 0 0" />
      <geometry>
        <cylinder radius="0.5" length="1" />
      </geometry>
    </collision>
    <inertial>
      <origin xyz="0 0 0" rpy="0 0 0" />
      <mass value="1" />
      <inertia ixx="0.3333333333333333" ixy="0" ixz="0" iyy="0.5" iyz="0" izz="0.3333333333333333" />
    </inertial>
  </link>
</robot>